Traceback (most recent call last):
  File "/opt/hostedtoolcache/Python/3.8.12/x64/lib/python3.8/site-packages/jupyter_cache/executors/utils.py", line 51, in single_nb_execution
    executenb(
  File "/opt/hostedtoolcache/Python/3.8.12/x64/lib/python3.8/site-packages/nbclient/client.py", line 1093, in execute
    return NotebookClient(nb=nb, resources=resources, km=km, **kwargs).execute()
  File "/opt/hostedtoolcache/Python/3.8.12/x64/lib/python3.8/site-packages/nbclient/util.py", line 84, in wrapped
    return just_run(coro(*args, **kwargs))
  File "/opt/hostedtoolcache/Python/3.8.12/x64/lib/python3.8/site-packages/nbclient/util.py", line 62, in just_run
    return loop.run_until_complete(coro)
  File "/opt/hostedtoolcache/Python/3.8.12/x64/lib/python3.8/asyncio/base_events.py", line 616, in run_until_complete
    return future.result()
  File "/opt/hostedtoolcache/Python/3.8.12/x64/lib/python3.8/site-packages/nbclient/client.py", line 559, in async_execute
    await self.async_execute_cell(
  File "/opt/hostedtoolcache/Python/3.8.12/x64/lib/python3.8/site-packages/nbclient/client.py", line 854, in async_execute_cell
    self._check_raise_for_error(cell, exec_reply)
  File "/opt/hostedtoolcache/Python/3.8.12/x64/lib/python3.8/site-packages/nbclient/client.py", line 756, in _check_raise_for_error
    raise CellExecutionError.from_cell_and_msg(cell, exec_reply_content)
nbclient.exceptions.CellExecutionError: An error occurred while executing the following cell:
------------------
# ËÆ°ÁÆó‰ººÁÑ∂ Likelihood
likelihood_current = norm(mu_current, 1).pdf(data).prod()
likelihood_proposal = norm(mu_proposal, 1).pdf(data).prod()

# ËÆ°ÁÆóÂÖàÈ™å Prior        
prior_current = norm(mu_prior_mu, mu_prior_sd).pdf(mu_current)
prior_proposal = norm(mu_prior_mu, mu_prior_sd).pdf(mu_proposal)

# ËÆ°ÁÆóÂàÜÂ≠êÈ°π Nominator of Bayes formula
p_current = likelihood_current * prior_current
p_proposal = likelihood_proposal * prior_proposal
------------------

[0;31m---------------------------------------------------------------------------[0m
[0;31mNameError[0m                                 Traceback (most recent call last)
[0;32m/tmp/ipykernel_1728/2231315902.py[0m in [0;36m<module>[0;34m[0m
[1;32m      4[0m [0;34m[0m[0m
[1;32m      5[0m [0;31m# ËÆ°ÁÆóÂÖàÈ™å Prior[0m[0;34m[0m[0;34m[0m[0;34m[0m[0m
[0;32m----> 6[0;31m [0mprior_current[0m [0;34m=[0m [0mnorm[0m[0;34m([0m[0mmu_prior_mu[0m[0;34m,[0m [0mmu_prior_sd[0m[0;34m)[0m[0;34m.[0m[0mpdf[0m[0;34m([0m[0mmu_current[0m[0;34m)[0m[0;34m[0m[0;34m[0m[0m
[0m[1;32m      7[0m [0mprior_proposal[0m [0;34m=[0m [0mnorm[0m[0;34m([0m[0mmu_prior_mu[0m[0;34m,[0m [0mmu_prior_sd[0m[0;34m)[0m[0;34m.[0m[0mpdf[0m[0;34m([0m[0mmu_proposal[0m[0;34m)[0m[0;34m[0m[0;34m[0m[0m
[1;32m      8[0m [0;34m[0m[0m

[0;31mNameError[0m: name 'mu_prior_mu' is not defined
NameError: name 'mu_prior_mu' is not defined

