Traceback (most recent call last):
  File "/opt/hostedtoolcache/Python/3.8.12/x64/lib/python3.8/site-packages/nbclient/client.py", line 627, in _async_poll_for_reply
    msg = await ensure_async(self.kc.shell_channel.get_msg(timeout=new_timeout))
  File "/opt/hostedtoolcache/Python/3.8.12/x64/lib/python3.8/site-packages/nbclient/util.py", line 89, in ensure_async
    result = await obj
  File "/opt/hostedtoolcache/Python/3.8.12/x64/lib/python3.8/site-packages/jupyter_client/channels.py", line 230, in get_msg
    raise Empty
_queue.Empty

During handling of the above exception, another exception occurred:

Traceback (most recent call last):
  File "/opt/hostedtoolcache/Python/3.8.12/x64/lib/python3.8/site-packages/jupyter_cache/executors/utils.py", line 51, in single_nb_execution
    executenb(
  File "/opt/hostedtoolcache/Python/3.8.12/x64/lib/python3.8/site-packages/nbclient/client.py", line 1117, in execute
    return NotebookClient(nb=nb, resources=resources, km=km, **kwargs).execute()
  File "/opt/hostedtoolcache/Python/3.8.12/x64/lib/python3.8/site-packages/nbclient/util.py", line 78, in wrapped
    return just_run(coro(*args, **kwargs))
  File "/opt/hostedtoolcache/Python/3.8.12/x64/lib/python3.8/site-packages/nbclient/util.py", line 57, in just_run
    return loop.run_until_complete(coro)
  File "/opt/hostedtoolcache/Python/3.8.12/x64/lib/python3.8/asyncio/base_events.py", line 616, in run_until_complete
    return future.result()
  File "/opt/hostedtoolcache/Python/3.8.12/x64/lib/python3.8/site-packages/nbclient/client.py", line 558, in async_execute
    await self.async_execute_cell(
  File "/opt/hostedtoolcache/Python/3.8.12/x64/lib/python3.8/site-packages/nbclient/client.py", line 846, in async_execute_cell
    exec_reply = await self.task_poll_for_reply
  File "/opt/hostedtoolcache/Python/3.8.12/x64/lib/python3.8/site-packages/nbclient/client.py", line 651, in _async_poll_for_reply
    await self._async_handle_timeout(timeout, cell)
  File "/opt/hostedtoolcache/Python/3.8.12/x64/lib/python3.8/site-packages/nbclient/client.py", line 701, in _async_handle_timeout
    raise CellTimeoutError.error_from_timeout_and_cell(
nbclient.exceptions.CellTimeoutError: A cell timed out while it was being executed, after 30 seconds.
The message was: Cell execution timed out.
Here is a preview of the cell contents:
-------------------
['with pm.Model() as normal_approximation:', '     # Beta先验', "     p = pm.Beta('p', 1., 1.)", '     # 二项似然', "     w = pm.Binomial('w',n=1, p=p, observed=data)"]
...
['     mean_q = pm.find_MAP()', '     std_q = ((1/pm.find_hessian(mean_q, vars=[p]))**0.5)[0] ', '     ', '     #输出近似高斯分布 q 的均值和标准差', "     mean_q['p'], std_q"]
-------------------

