Traceback (most recent call last):
  File "/opt/hostedtoolcache/Python/3.8.11/x64/lib/python3.8/site-packages/jupyter_cache/executors/utils.py", line 51, in single_nb_execution
    executenb(
  File "/opt/hostedtoolcache/Python/3.8.11/x64/lib/python3.8/site-packages/nbclient/client.py", line 1117, in execute
    return NotebookClient(nb=nb, resources=resources, km=km, **kwargs).execute()
  File "/opt/hostedtoolcache/Python/3.8.11/x64/lib/python3.8/site-packages/nbclient/util.py", line 78, in wrapped
    return just_run(coro(*args, **kwargs))
  File "/opt/hostedtoolcache/Python/3.8.11/x64/lib/python3.8/site-packages/nbclient/util.py", line 57, in just_run
    return loop.run_until_complete(coro)
  File "/opt/hostedtoolcache/Python/3.8.11/x64/lib/python3.8/asyncio/base_events.py", line 616, in run_until_complete
    return future.result()
  File "/opt/hostedtoolcache/Python/3.8.11/x64/lib/python3.8/site-packages/nbclient/client.py", line 558, in async_execute
    await self.async_execute_cell(
  File "/opt/hostedtoolcache/Python/3.8.11/x64/lib/python3.8/site-packages/nbclient/client.py", line 862, in async_execute_cell
    self._check_raise_for_error(cell, exec_reply)
  File "/opt/hostedtoolcache/Python/3.8.11/x64/lib/python3.8/site-packages/nbclient/client.py", line 765, in _check_raise_for_error
    raise CellExecutionError.from_cell_and_msg(cell, exec_reply_content)
nbclient.exceptions.CellExecutionError: An error occurred while executing the following cell:
------------------
dummy_data = np.loadtxt('../data/dummy.csv')
x_1 = dummy_data[:, 0]
y_1 = dummy_data[:, 1]
order = 2
x_1p = np.vstack([x_1**i for i in range(1, order+1)])
x_1s = (x_1p - x_1p.mean(axis=1, keepdims=True)) / x_1p.std(axis=1, keepdims=True)
y_1s = (y_1 - y_1.mean()) / y_1.std()
plt.scatter(x_1s[0], y_1s)
plt.xlabel('x')
plt.ylabel('y')
------------------

[0;31m---------------------------------------------------------------------------[0m
[0;31mNameError[0m                                 Traceback (most recent call last)
[0;32m/tmp/ipykernel_2021/1113835353.py[0m in [0;36m<module>[0;34m[0m
[0;32m----> 1[0;31m [0mdummy_data[0m [0;34m=[0m [0mnp[0m[0;34m.[0m[0mloadtxt[0m[0;34m([0m[0;34m'../data/dummy.csv'[0m[0;34m)[0m[0;34m[0m[0;34m[0m[0m
[0m[1;32m      2[0m [0mx_1[0m [0;34m=[0m [0mdummy_data[0m[0;34m[[0m[0;34m:[0m[0;34m,[0m [0;36m0[0m[0;34m][0m[0;34m[0m[0;34m[0m[0m
[1;32m      3[0m [0my_1[0m [0;34m=[0m [0mdummy_data[0m[0;34m[[0m[0;34m:[0m[0;34m,[0m [0;36m1[0m[0;34m][0m[0;34m[0m[0;34m[0m[0m
[1;32m      4[0m [0morder[0m [0;34m=[0m [0;36m2[0m[0;34m[0m[0;34m[0m[0m
[1;32m      5[0m [0mx_1p[0m [0;34m=[0m [0mnp[0m[0;34m.[0m[0mvstack[0m[0;34m([0m[0;34m[[0m[0mx_1[0m[0;34m**[0m[0mi[0m [0;32mfor[0m [0mi[0m [0;32min[0m [0mrange[0m[0;34m([0m[0;36m1[0m[0;34m,[0m [0morder[0m[0;34m+[0m[0;36m1[0m[0;34m)[0m[0;34m][0m[0;34m)[0m[0;34m[0m[0;34m[0m[0m

[0;31mNameError[0m: name 'np' is not defined
NameError: name 'np' is not defined

